ERROR 2016-05-10 11:48:43,802 base 3504 3992 Internal Server Error: /admin/greedyMusic/track_details/add/
Traceback (most recent call last):
  File "E:\CStone\python\lib\site-packages\django\core\handlers\base.py", line 132, in get_response
    response = wrapped_callback(request, *callback_args, **callback_kwargs)
  File "E:\CStone\python\lib\site-packages\django\contrib\admin\options.py", line 616, in wrapper
    return self.admin_site.admin_view(view)(*args, **kwargs)
  File "E:\CStone\python\lib\site-packages\django\utils\decorators.py", line 110, in _wrapped_view
    response = view_func(request, *args, **kwargs)
  File "E:\CStone\python\lib\site-packages\django\views\decorators\cache.py", line 57, in _wrapped_view_func
    response = view_func(request, *args, **kwargs)
  File "E:\CStone\python\lib\site-packages\django\contrib\admin\sites.py", line 233, in inner
    return view(request, *args, **kwargs)
  File "E:\CStone\python\lib\site-packages\django\contrib\admin\options.py", line 1516, in add_view
    return self.changeform_view(request, None, form_url, extra_context)
  File "E:\CStone\python\lib\site-packages\django\utils\decorators.py", line 34, in _wrapper
    return bound_func(*args, **kwargs)
  File "E:\CStone\python\lib\site-packages\django\utils\decorators.py", line 110, in _wrapped_view
    response = view_func(request, *args, **kwargs)
  File "E:\CStone\python\lib\site-packages\django\utils\decorators.py", line 30, in bound_func
    return func.__get__(self, type(self))(*args2, **kwargs2)
  File "E:\CStone\python\lib\site-packages\django\utils\decorators.py", line 145, in inner
    return func(*args, **kwargs)
  File "E:\CStone\python\lib\site-packages\django\contrib\admin\options.py", line 1470, in changeform_view
    self.log_addition(request, new_object)
  File "E:\CStone\python\lib\site-packages\django\contrib\admin\options.py", line 810, in log_addition
    object_repr=force_text(object),
  File "E:\CStone\python\lib\site-packages\django\utils\encoding.py", line 92, in force_text
    s = six.text_type(s)
  File "E:\GreedyGames\greedyMusic\models.py", line 14, in __unicode__
    return '%s %s' % (self.Genre,self.Title)
AttributeError: 'Track_Details' object has no attribute 'Genre'
ERROR 2016-05-10 11:58:08,032 base 2424 1380 Internal Server Error: /tracks/
Traceback (most recent call last):
  File "E:\CStone\python\lib\site-packages\django\core\handlers\base.py", line 132, in get_response
    response = wrapped_callback(request, *callback_args, **callback_kwargs)
  File "E:\CStone\python\lib\site-packages\django\views\generic\base.py", line 71, in view
    return self.dispatch(request, *args, **kwargs)
  File "E:\CStone\python\lib\site-packages\django\views\generic\base.py", line 89, in dispatch
    return handler(request, *args, **kwargs)
  File "E:\CStone\python\lib\site-packages\django\views\generic\list.py", line 159, in get
    self.object_list = self.get_queryset()
  File "E:\CStone\python\lib\site-packages\django\views\generic\list.py", line 38, in get_queryset
    queryset = self.model._default_manager.all()
AttributeError: 'QuerySet' object has no attribute '_default_manager'
ERROR 2016-05-10 12:06:39,556 base 248 4404 Internal Server Error: /tracks/
Traceback (most recent call last):
  File "E:\CStone\python\lib\site-packages\django\core\handlers\base.py", line 132, in get_response
    response = wrapped_callback(request, *callback_args, **callback_kwargs)
  File "E:\CStone\python\lib\site-packages\django\views\generic\base.py", line 71, in view
    return self.dispatch(request, *args, **kwargs)
  File "E:\CStone\python\lib\site-packages\django\views\generic\base.py", line 89, in dispatch
    return handler(request, *args, **kwargs)
  File "E:\CStone\python\lib\site-packages\django\views\generic\list.py", line 159, in get
    self.object_list = self.get_queryset()
  File "E:\CStone\python\lib\site-packages\django\views\generic\list.py", line 38, in get_queryset
    queryset = self.model._default_manager.all()
AttributeError: 'QuerySet' object has no attribute '_default_manager'
ERROR 2016-05-10 13:06:28,506 base 6536 5012 Internal Server Error: /genre/
Traceback (most recent call last):
  File "E:\CStone\python\lib\site-packages\django\core\handlers\base.py", line 132, in get_response
    response = wrapped_callback(request, *callback_args, **callback_kwargs)
  File "E:\GreedyGames\greedyMusic\views.py", line 24, in viewGenre
    return render_to_response('genre.html', genreDict,context_instance=RequestContext(request))
  File "E:\CStone\python\lib\site-packages\django\shortcuts.py", line 45, in render_to_response
    using=using)
  File "E:\CStone\python\lib\site-packages\django\template\loader.py", line 116, in render_to_string
    template_name, context, context_instance, dirs, dictionary)
  File "E:\CStone\python\lib\site-packages\django\template\engine.py", line 220, in render_to_string
    with context_instance.push(context):
  File "E:\CStone\python\lib\site-packages\django\template\context.py", line 55, in push
    return ContextDict(self, *args, **kwargs)
  File "E:\CStone\python\lib\site-packages\django\template\context.py", line 20, in __init__
    super(ContextDict, self).__init__(*args, **kwargs)
TypeError: cannot convert dictionary update sequence element #0 to a sequence
ERROR 2016-05-10 13:07:45,832 base 4648 4596 Internal Server Error: /genre/
Traceback (most recent call last):
  File "E:\CStone\python\lib\site-packages\django\core\handlers\base.py", line 132, in get_response
    response = wrapped_callback(request, *callback_args, **callback_kwargs)
  File "E:\GreedyGames\greedyMusic\views.py", line 25, in viewGenre
    return render_to_response('genre.html', genreDict,context_instance=RequestContext(request))
  File "E:\CStone\python\lib\site-packages\django\shortcuts.py", line 45, in render_to_response
    using=using)
  File "E:\CStone\python\lib\site-packages\django\template\loader.py", line 116, in render_to_string
    template_name, context, context_instance, dirs, dictionary)
  File "E:\CStone\python\lib\site-packages\django\template\engine.py", line 220, in render_to_string
    with context_instance.push(context):
  File "E:\CStone\python\lib\site-packages\django\template\context.py", line 55, in push
    return ContextDict(self, *args, **kwargs)
  File "E:\CStone\python\lib\site-packages\django\template\context.py", line 20, in __init__
    super(ContextDict, self).__init__(*args, **kwargs)
TypeError: cannot convert dictionary update sequence element #0 to a sequence
ERROR 2016-05-10 13:18:52,956 base 6432 2580 Internal Server Error: /genre/
Traceback (most recent call last):
  File "E:\CStone\python\lib\site-packages\django\core\handlers\base.py", line 132, in get_response
    response = wrapped_callback(request, *callback_args, **callback_kwargs)
  File "E:\GreedyGames\greedyMusic\views.py", line 25, in viewGenre
    return render_to_response('genre.html', genreDict,context_instance=RequestContext(request))
  File "E:\CStone\python\lib\site-packages\django\shortcuts.py", line 45, in render_to_response
    using=using)
  File "E:\CStone\python\lib\site-packages\django\template\loader.py", line 116, in render_to_string
    template_name, context, context_instance, dirs, dictionary)
  File "E:\CStone\python\lib\site-packages\django\template\engine.py", line 220, in render_to_string
    with context_instance.push(context):
  File "E:\CStone\python\lib\site-packages\django\template\context.py", line 55, in push
    return ContextDict(self, *args, **kwargs)
  File "E:\CStone\python\lib\site-packages\django\template\context.py", line 20, in __init__
    super(ContextDict, self).__init__(*args, **kwargs)
TypeError: cannot convert dictionary update sequence element #0 to a sequence
ERROR 2016-05-10 13:19:39,273 base 6432 4296 Internal Server Error: /genre/
Traceback (most recent call last):
  File "E:\CStone\python\lib\site-packages\django\core\handlers\base.py", line 132, in get_response
    response = wrapped_callback(request, *callback_args, **callback_kwargs)
  File "E:\GreedyGames\greedyMusic\views.py", line 25, in viewGenre
    return render_to_response('genre.html', genreDict,context_instance=RequestContext(request))
  File "E:\CStone\python\lib\site-packages\django\shortcuts.py", line 45, in render_to_response
    using=using)
  File "E:\CStone\python\lib\site-packages\django\template\loader.py", line 116, in render_to_string
    template_name, context, context_instance, dirs, dictionary)
  File "E:\CStone\python\lib\site-packages\django\template\engine.py", line 220, in render_to_string
    with context_instance.push(context):
  File "E:\CStone\python\lib\site-packages\django\template\context.py", line 55, in push
    return ContextDict(self, *args, **kwargs)
  File "E:\CStone\python\lib\site-packages\django\template\context.py", line 20, in __init__
    super(ContextDict, self).__init__(*args, **kwargs)
TypeError: cannot convert dictionary update sequence element #0 to a sequence
ERROR 2016-05-10 13:21:09,967 base 6256 6048 Internal Server Error: /genre/
Traceback (most recent call last):
  File "E:\CStone\python\lib\site-packages\django\core\handlers\base.py", line 132, in get_response
    response = wrapped_callback(request, *callback_args, **callback_kwargs)
  File "E:\GreedyGames\greedyMusic\views.py", line 26, in viewGenre
    return render_to_response('genre.html', genreList,context_instance=RequestContext(request))
  File "E:\CStone\python\lib\site-packages\django\shortcuts.py", line 45, in render_to_response
    using=using)
  File "E:\CStone\python\lib\site-packages\django\template\loader.py", line 116, in render_to_string
    template_name, context, context_instance, dirs, dictionary)
  File "E:\CStone\python\lib\site-packages\django\template\engine.py", line 220, in render_to_string
    with context_instance.push(context):
  File "E:\CStone\python\lib\site-packages\django\template\context.py", line 55, in push
    return ContextDict(self, *args, **kwargs)
  File "E:\CStone\python\lib\site-packages\django\template\context.py", line 20, in __init__
    super(ContextDict, self).__init__(*args, **kwargs)
ValueError: dictionary update sequence element #0 has length 5; 2 is required
ERROR 2016-05-10 13:22:32,927 base 6256 3812 Internal Server Error: /genre/
Traceback (most recent call last):
  File "E:\CStone\python\lib\site-packages\django\core\handlers\base.py", line 132, in get_response
    response = wrapped_callback(request, *callback_args, **callback_kwargs)
  File "E:\GreedyGames\greedyMusic\views.py", line 26, in viewGenre
    return render_to_response('genre.html', genreList,context_instance=RequestContext(request))
  File "E:\CStone\python\lib\site-packages\django\shortcuts.py", line 45, in render_to_response
    using=using)
  File "E:\CStone\python\lib\site-packages\django\template\loader.py", line 116, in render_to_string
    template_name, context, context_instance, dirs, dictionary)
  File "E:\CStone\python\lib\site-packages\django\template\engine.py", line 220, in render_to_string
    with context_instance.push(context):
  File "E:\CStone\python\lib\site-packages\django\template\context.py", line 55, in push
    return ContextDict(self, *args, **kwargs)
  File "E:\CStone\python\lib\site-packages\django\template\context.py", line 20, in __init__
    super(ContextDict, self).__init__(*args, **kwargs)
ValueError: dictionary update sequence element #0 has length 5; 2 is required
ERROR 2016-05-10 13:27:03,543 base 5764 4296 Internal Server Error: /genre/
Traceback (most recent call last):
  File "E:\CStone\python\lib\site-packages\django\core\handlers\base.py", line 132, in get_response
    response = wrapped_callback(request, *callback_args, **callback_kwargs)
  File "E:\GreedyGames\greedyMusic\views.py", line 25, in viewGenre
    return render_to_response('genre.html', genreList,context_instance=RequestContext(request))
  File "E:\CStone\python\lib\site-packages\django\shortcuts.py", line 45, in render_to_response
    using=using)
  File "E:\CStone\python\lib\site-packages\django\template\loader.py", line 116, in render_to_string
    template_name, context, context_instance, dirs, dictionary)
  File "E:\CStone\python\lib\site-packages\django\template\engine.py", line 220, in render_to_string
    with context_instance.push(context):
  File "E:\CStone\python\lib\site-packages\django\template\context.py", line 55, in push
    return ContextDict(self, *args, **kwargs)
  File "E:\CStone\python\lib\site-packages\django\template\context.py", line 20, in __init__
    super(ContextDict, self).__init__(*args, **kwargs)
TypeError: cannot convert dictionary update sequence element #0 to a sequence
ERROR 2016-05-10 13:32:47,187 base 5272 4484 Internal Server Error: /genre/
Traceback (most recent call last):
  File "E:\CStone\python\lib\site-packages\django\core\handlers\base.py", line 132, in get_response
    response = wrapped_callback(request, *callback_args, **callback_kwargs)
  File "E:\GreedyGames\greedyMusic\views.py", line 25, in viewGenre
    return render_to_response('genre.html', genreList,context_instance=RequestContext(request))
  File "E:\CStone\python\lib\site-packages\django\shortcuts.py", line 45, in render_to_response
    using=using)
  File "E:\CStone\python\lib\site-packages\django\template\loader.py", line 116, in render_to_string
    template_name, context, context_instance, dirs, dictionary)
  File "E:\CStone\python\lib\site-packages\django\template\engine.py", line 220, in render_to_string
    with context_instance.push(context):
  File "E:\CStone\python\lib\site-packages\django\template\context.py", line 55, in push
    return ContextDict(self, *args, **kwargs)
  File "E:\CStone\python\lib\site-packages\django\template\context.py", line 20, in __init__
    super(ContextDict, self).__init__(*args, **kwargs)
TypeError: cannot convert dictionary update sequence element #0 to a sequence
ERROR 2016-05-10 13:37:16,341 base 6280 3656 Internal Server Error: /genre/
Traceback (most recent call last):
  File "E:\CStone\python\lib\site-packages\django\core\handlers\base.py", line 132, in get_response
    response = wrapped_callback(request, *callback_args, **callback_kwargs)
  File "E:\GreedyGames\greedyMusic\views.py", line 28, in viewGenre
    return render_to_response('genre.html', genreList,context_instance=RequestContext(request))
  File "E:\CStone\python\lib\site-packages\django\shortcuts.py", line 45, in render_to_response
    using=using)
  File "E:\CStone\python\lib\site-packages\django\template\loader.py", line 116, in render_to_string
    template_name, context, context_instance, dirs, dictionary)
  File "E:\CStone\python\lib\site-packages\django\template\engine.py", line 220, in render_to_string
    with context_instance.push(context):
  File "E:\CStone\python\lib\site-packages\django\template\context.py", line 55, in push
    return ContextDict(self, *args, **kwargs)
  File "E:\CStone\python\lib\site-packages\django\template\context.py", line 20, in __init__
    super(ContextDict, self).__init__(*args, **kwargs)
TypeError: cannot convert dictionary update sequence element #0 to a sequence
ERROR 2016-05-10 14:13:01,207 base 6560 1732 Internal Server Error: /addNewGenre/
Traceback (most recent call last):
  File "E:\CStone\python\lib\site-packages\django\core\handlers\base.py", line 132, in get_response
    response = wrapped_callback(request, *callback_args, **callback_kwargs)
  File "E:\GreedyGames\greedyMusic\views.py", line 53, in insertGenre
    genreDetailsDict['name'] = request.POST['name']
  File "E:\CStone\python\lib\site-packages\django\utils\datastructures.py", line 322, in __getitem__
    raise MultiValueDictKeyError(repr(key))
MultiValueDictKeyError: "'name'"
ERROR 2016-05-10 15:44:33,453 base 3764 6160 Internal Server Error: /addNewGenre/
Traceback (most recent call last):
  File "E:\CStone\python\lib\site-packages\django\core\handlers\base.py", line 132, in get_response
    response = wrapped_callback(request, *callback_args, **callback_kwargs)
  File "E:\GreedyGames\greedyMusic\views.py", line 61, in insertGenre
    post.name = request.name
AttributeError: 'WSGIRequest' object has no attribute 'name'
ERROR 2016-05-10 15:46:06,434 base 5112 3852 Internal Server Error: /addNewGenre/
Traceback (most recent call last):
  File "E:\CStone\python\lib\site-packages\django\core\handlers\base.py", line 132, in get_response
    response = wrapped_callback(request, *callback_args, **callback_kwargs)
  File "E:\GreedyGames\greedyMusic\views.py", line 62, in insertGenre
    post.name = request.Name
AttributeError: 'WSGIRequest' object has no attribute 'Name'
ERROR 2016-05-10 15:47:24,691 base 5644 6372 Internal Server Error: /addNewGenre/
Traceback (most recent call last):
  File "E:\CStone\python\lib\site-packages\django\core\handlers\base.py", line 132, in get_response
    response = wrapped_callback(request, *callback_args, **callback_kwargs)
  File "E:\GreedyGames\greedyMusic\views.py", line 62, in insertGenre
    post.name = request.Name
AttributeError: 'WSGIRequest' object has no attribute 'Name'
ERROR 2016-05-10 15:48:45,312 base 3820 6628 Internal Server Error: /addNewGenre/
Traceback (most recent call last):
  File "E:\CStone\python\lib\site-packages\django\core\handlers\base.py", line 132, in get_response
    response = wrapped_callback(request, *callback_args, **callback_kwargs)
  File "E:\GreedyGames\greedyMusic\views.py", line 62, in insertGenre
    post.name = request.POST.Name
AttributeError: 'QueryDict' object has no attribute 'Name'
ERROR 2016-05-10 15:51:04,638 base 5672 5112 Internal Server Error: /addNewGenre/
Traceback (most recent call last):
  File "E:\CStone\python\lib\site-packages\django\core\handlers\base.py", line 132, in get_response
    response = wrapped_callback(request, *callback_args, **callback_kwargs)
  File "E:\GreedyGames\greedyMusic\views.py", line 61, in insertGenre
    print request.POST.QueryDict
AttributeError: 'QueryDict' object has no attribute 'QueryDict'
ERROR 2016-05-10 15:51:53,269 base 6824 6676 Internal Server Error: /addNewGenre/
Traceback (most recent call last):
  File "E:\CStone\python\lib\site-packages\django\core\handlers\base.py", line 132, in get_response
    response = wrapped_callback(request, *callback_args, **callback_kwargs)
  File "E:\GreedyGames\greedyMusic\views.py", line 62, in insertGenre
    print request.POST.QueryDict.Name
AttributeError: 'QueryDict' object has no attribute 'QueryDict'
ERROR 2016-05-10 16:03:10,365 base 4800 5292 Internal Server Error: /addNewTrack/
Traceback (most recent call last):
  File "E:\CStone\python\lib\site-packages\django\core\handlers\base.py", line 132, in get_response
    response = wrapped_callback(request, *callback_args, **callback_kwargs)
  File "E:\GreedyGames\greedyMusic\views.py", line 41, in insertTracks
    return redirect('viewTrack')
  File "E:\CStone\python\lib\site-packages\django\shortcuts.py", line 116, in redirect
    return redirect_class(resolve_url(to, *args, **kwargs))
  File "E:\CStone\python\lib\site-packages\django\shortcuts.py", line 205, in resolve_url
    return urlresolvers.reverse(to, args=args, kwargs=kwargs)
  File "E:\CStone\python\lib\site-packages\django\core\urlresolvers.py", line 579, in reverse
    return force_text(iri_to_uri(resolver._reverse_with_prefix(view, prefix, *args, **kwargs)))
  File "E:\CStone\python\lib\site-packages\django\core\urlresolvers.py", line 496, in _reverse_with_prefix
    (lookup_view_s, args, kwargs, len(patterns), patterns))
NoReverseMatch: Reverse for 'viewTrack' with arguments '()' and keyword arguments '{}' not found. 0 pattern(s) tried: []
ERROR 2016-05-10 16:18:57,641 base 5704 5088 Internal Server Error: /addNewTrack/
Traceback (most recent call last):
  File "E:\CStone\python\lib\site-packages\django\core\handlers\base.py", line 132, in get_response
    response = wrapped_callback(request, *callback_args, **callback_kwargs)
  File "E:\GreedyGames\greedyMusic\views.py", line 44, in insertTracks
    form.ModelMultipleChoiceField(queryset=Track_Genre.objects.all())
AttributeError: 'FormForTrack' object has no attribute 'ModelMultipleChoiceField'
ERROR 2016-05-10 16:31:57,769 base 6212 2084 Internal Server Error: /tracks/
Traceback (most recent call last):
  File "E:\CStone\python\lib\site-packages\django\core\handlers\base.py", line 119, in get_response
    resolver_match = resolver.resolve(request.path_info)
  File "E:\CStone\python\lib\site-packages\django\core\urlresolvers.py", line 366, in resolve
    for pattern in self.url_patterns:
  File "E:\CStone\python\lib\site-packages\django\core\urlresolvers.py", line 402, in url_patterns
    patterns = getattr(self.urlconf_module, "urlpatterns", self.urlconf_module)
  File "E:\CStone\python\lib\site-packages\django\core\urlresolvers.py", line 396, in urlconf_module
    self._urlconf_module = import_module(self.urlconf_name)
  File "E:\CStone\python\lib\importlib\__init__.py", line 37, in import_module
    __import__(name)
  File "E:\GreedyGames\greedyMusic\urls.py", line 18, in <module>
    from .views import *
  File "E:\GreedyGames\greedyMusic\views.py", line 2, in <module>
    from models import Track_Details,Track_Genre,Track_Genre_Mapping,TrackRequestForm
ImportError: cannot import name TrackRequestForm
ERROR 2016-05-10 16:32:34,221 base 1672 5096 Internal Server Error: /tracks/
Traceback (most recent call last):
  File "E:\CStone\python\lib\site-packages\django\core\handlers\base.py", line 119, in get_response
    resolver_match = resolver.resolve(request.path_info)
  File "E:\CStone\python\lib\site-packages\django\core\urlresolvers.py", line 366, in resolve
    for pattern in self.url_patterns:
  File "E:\CStone\python\lib\site-packages\django\core\urlresolvers.py", line 402, in url_patterns
    patterns = getattr(self.urlconf_module, "urlpatterns", self.urlconf_module)
  File "E:\CStone\python\lib\site-packages\django\core\urlresolvers.py", line 396, in urlconf_module
    self._urlconf_module = import_module(self.urlconf_name)
  File "E:\CStone\python\lib\importlib\__init__.py", line 37, in import_module
    __import__(name)
  File "E:\GreedyGames\greedyMusic\urls.py", line 18, in <module>
    from .views import *
  File "E:\GreedyGames\greedyMusic\views.py", line 6, in <module>
    from .forms import FormForGenre,FormForTrack,FormForTrackGenreMap,TrackRequestForm
  File "E:\GreedyGames\greedyMusic\forms.py", line 19, in <module>
    class TrackRequestForm(forms.ModelForm):
  File "E:\CStone\python\lib\site-packages\django\forms\models.py", line 295, in __new__
    raise FieldError(message)
FieldError: Unknown field(s) (Stars, Title) specified for Track_Genre
ERROR 2016-05-10 18:06:43,924 base 6408 2440 Internal Server Error: /admin
Traceback (most recent call last):
  File "E:\CStone\python\lib\site-packages\django\core\handlers\base.py", line 108, in get_response
    response = middleware_method(request)
  File "E:\CStone\python\lib\site-packages\django\middleware\common.py", line 74, in process_request
    if (not urlresolvers.is_valid_path(request.path_info, urlconf) and
  File "E:\CStone\python\lib\site-packages\django\core\urlresolvers.py", line 647, in is_valid_path
    resolve(path, urlconf)
  File "E:\CStone\python\lib\site-packages\django\core\urlresolvers.py", line 522, in resolve
    return get_resolver(urlconf).resolve(path)
  File "E:\CStone\python\lib\site-packages\django\core\urlresolvers.py", line 366, in resolve
    for pattern in self.url_patterns:
  File "E:\CStone\python\lib\site-packages\django\core\urlresolvers.py", line 402, in url_patterns
    patterns = getattr(self.urlconf_module, "urlpatterns", self.urlconf_module)
  File "E:\CStone\python\lib\site-packages\django\core\urlresolvers.py", line 396, in urlconf_module
    self._urlconf_module = import_module(self.urlconf_name)
  File "E:\CStone\python\lib\importlib\__init__.py", line 37, in import_module
    __import__(name)
  File "E:\GreedyGames\greedyMusic\urls.py", line 18, in <module>
    from .views import *
  File "E:\GreedyGames\greedyMusic\views.py", line 6, in <module>
    from .forms import FormForGenre,FormForTrack,TrackRequestForm
  File "E:\GreedyGames\greedyMusic\forms.py", line 2, in <module>
    from .models import Track_Genre,Track_Details
ImportError: cannot import name Track_Genre
ERROR 2016-05-10 18:09:45,644 base 1904 5380 Internal Server Error: /admin
Traceback (most recent call last):
  File "E:\CStone\python\lib\site-packages\django\core\handlers\base.py", line 108, in get_response
    response = middleware_method(request)
  File "E:\CStone\python\lib\site-packages\django\middleware\common.py", line 74, in process_request
    if (not urlresolvers.is_valid_path(request.path_info, urlconf) and
  File "E:\CStone\python\lib\site-packages\django\core\urlresolvers.py", line 647, in is_valid_path
    resolve(path, urlconf)
  File "E:\CStone\python\lib\site-packages\django\core\urlresolvers.py", line 522, in resolve
    return get_resolver(urlconf).resolve(path)
  File "E:\CStone\python\lib\site-packages\django\core\urlresolvers.py", line 366, in resolve
    for pattern in self.url_patterns:
  File "E:\CStone\python\lib\site-packages\django\core\urlresolvers.py", line 402, in url_patterns
    patterns = getattr(self.urlconf_module, "urlpatterns", self.urlconf_module)
  File "E:\CStone\python\lib\site-packages\django\core\urlresolvers.py", line 396, in urlconf_module
    self._urlconf_module = import_module(self.urlconf_name)
  File "E:\CStone\python\lib\importlib\__init__.py", line 37, in import_module
    __import__(name)
  File "E:\GreedyGames\greedyMusic\urls.py", line 18, in <module>
    from .views import *
  File "E:\GreedyGames\greedyMusic\views.py", line 6, in <module>
    from .forms import FormForGenre,TrackRequestForm
  File "E:\GreedyGames\greedyMusic\forms.py", line 19, in <module>
    class TrackRequestForm(forms.ModelForm):
  File "E:\CStone\python\lib\site-packages\django\forms\models.py", line 295, in __new__
    raise FieldError(message)
FieldError: Unknown field(s) (Genre) specified for Track
ERROR 2016-05-10 18:21:23,035 base 2844 3336 Internal Server Error: /tracks/
Traceback (most recent call last):
  File "E:\CStone\python\lib\site-packages\django\core\handlers\base.py", line 164, in get_response
    response = response.render()
  File "E:\CStone\python\lib\site-packages\django\template\response.py", line 158, in render
    self.content = self.rendered_content
  File "E:\CStone\python\lib\site-packages\django\template\response.py", line 135, in rendered_content
    content = template.render(context, self._request)
  File "E:\CStone\python\lib\site-packages\django\template\backends\django.py", line 74, in render
    return self.template.render(context)
  File "E:\CStone\python\lib\site-packages\django\template\base.py", line 209, in render
    return self._render(context)
  File "E:\CStone\python\lib\site-packages\django\template\base.py", line 201, in _render
    return self.nodelist.render(context)
  File "E:\CStone\python\lib\site-packages\django\template\base.py", line 903, in render
    bit = self.render_node(node, context)
  File "E:\CStone\python\lib\site-packages\django\template\debug.py", line 79, in render_node
    return node.render(context)
  File "E:\CStone\python\lib\site-packages\django\template\defaulttags.py", line 217, in render
    nodelist.append(node.render(context))
  File "E:\CStone\python\lib\site-packages\django\template\defaulttags.py", line 161, in render
    values = list(values)
TypeError: 'ManyRelatedManager' object is not iterable
ERROR 2016-05-10 19:45:01,369 base 1796 4000 Internal Server Error: /admin/
Traceback (most recent call last):
  File "E:\CStone\python\lib\site-packages\django\core\handlers\base.py", line 119, in get_response
    resolver_match = resolver.resolve(request.path_info)
  File "E:\CStone\python\lib\site-packages\django\core\urlresolvers.py", line 366, in resolve
    for pattern in self.url_patterns:
  File "E:\CStone\python\lib\site-packages\django\core\urlresolvers.py", line 402, in url_patterns
    patterns = getattr(self.urlconf_module, "urlpatterns", self.urlconf_module)
  File "E:\CStone\python\lib\site-packages\django\core\urlresolvers.py", line 396, in urlconf_module
    self._urlconf_module = import_module(self.urlconf_name)
  File "E:\CStone\python\lib\importlib\__init__.py", line 37, in import_module
    __import__(name)
  File "E:\GreedyGames\greedyMusic\urls.py", line 18, in <module>
    from .views import *
  File "E:\GreedyGames\greedyMusic\views.py", line 12, in <module>
    class TrackListView(ListView):
  File "E:\GreedyGames\greedyMusic\views.py", line 14, in TrackListView
    print trackAll[1]
  File "E:\CStone\python\lib\site-packages\django\db\models\query.py", line 201, in __getitem__
    return list(qs)[0]
IndexError: list index out of range
ERROR 2016-05-10 20:57:33,872 base 3972 6040 Internal Server Error: /tracks/
Traceback (most recent call last):
  File "E:\CStone\python\lib\site-packages\django\core\handlers\base.py", line 119, in get_response
    resolver_match = resolver.resolve(request.path_info)
  File "E:\CStone\python\lib\site-packages\django\core\urlresolvers.py", line 366, in resolve
    for pattern in self.url_patterns:
  File "E:\CStone\python\lib\site-packages\django\core\urlresolvers.py", line 402, in url_patterns
    patterns = getattr(self.urlconf_module, "urlpatterns", self.urlconf_module)
  File "E:\CStone\python\lib\site-packages\django\core\urlresolvers.py", line 396, in urlconf_module
    self._urlconf_module = import_module(self.urlconf_name)
  File "E:\CStone\python\lib\importlib\__init__.py", line 37, in import_module
    __import__(name)
  File "E:\GreedyGames\greedyMusic\urls.py", line 29, in <module>
    url(r'^search_results/',name='search_results'),
TypeError: url() takes at least 2 arguments (2 given)
ERROR 2016-05-10 20:58:47,937 base 3668 7132 Internal Server Error: /tracks/
Traceback (most recent call last):
  File "E:\CStone\python\lib\site-packages\django\core\handlers\base.py", line 164, in get_response
    response = response.render()
  File "E:\CStone\python\lib\site-packages\django\template\response.py", line 158, in render
    self.content = self.rendered_content
  File "E:\CStone\python\lib\site-packages\django\template\response.py", line 135, in rendered_content
    content = template.render(context, self._request)
  File "E:\CStone\python\lib\site-packages\django\template\backends\django.py", line 74, in render
    return self.template.render(context)
  File "E:\CStone\python\lib\site-packages\django\template\base.py", line 209, in render
    return self._render(context)
  File "E:\CStone\python\lib\site-packages\django\template\base.py", line 201, in _render
    return self.nodelist.render(context)
  File "E:\CStone\python\lib\site-packages\django\template\base.py", line 903, in render
    bit = self.render_node(node, context)
  File "E:\CStone\python\lib\site-packages\django\template\debug.py", line 79, in render_node
    return node.render(context)
  File "E:\CStone\python\lib\site-packages\django\template\defaulttags.py", line 507, in render
    six.reraise(*exc_info)
  File "E:\CStone\python\lib\site-packages\django\template\defaulttags.py", line 493, in render
    url = reverse(view_name, args=args, kwargs=kwargs, current_app=current_app)
  File "E:\CStone\python\lib\site-packages\django\core\urlresolvers.py", line 579, in reverse
    return force_text(iri_to_uri(resolver._reverse_with_prefix(view, prefix, *args, **kwargs)))
  File "E:\CStone\python\lib\site-packages\django\core\urlresolvers.py", line 496, in _reverse_with_prefix
    (lookup_view_s, args, kwargs, len(patterns), patterns))
NoReverseMatch: Reverse for '/search_results' with arguments '()' and keyword arguments '{}' not found. 0 pattern(s) tried: []
ERROR 2016-05-10 21:01:30,381 base 3668 6184 Internal Server Error: /tracks/
Traceback (most recent call last):
  File "E:\CStone\python\lib\site-packages\django\core\handlers\base.py", line 164, in get_response
    response = response.render()
  File "E:\CStone\python\lib\site-packages\django\template\response.py", line 158, in render
    self.content = self.rendered_content
  File "E:\CStone\python\lib\site-packages\django\template\response.py", line 135, in rendered_content
    content = template.render(context, self._request)
  File "E:\CStone\python\lib\site-packages\django\template\backends\django.py", line 74, in render
    return self.template.render(context)
  File "E:\CStone\python\lib\site-packages\django\template\base.py", line 209, in render
    return self._render(context)
  File "E:\CStone\python\lib\site-packages\django\template\base.py", line 201, in _render
    return self.nodelist.render(context)
  File "E:\CStone\python\lib\site-packages\django\template\base.py", line 903, in render
    bit = self.render_node(node, context)
  File "E:\CStone\python\lib\site-packages\django\template\debug.py", line 79, in render_node
    return node.render(context)
  File "E:\CStone\python\lib\site-packages\django\template\defaulttags.py", line 507, in render
    six.reraise(*exc_info)
  File "E:\CStone\python\lib\site-packages\django\template\defaulttags.py", line 493, in render
    url = reverse(view_name, args=args, kwargs=kwargs, current_app=current_app)
  File "E:\CStone\python\lib\site-packages\django\core\urlresolvers.py", line 579, in reverse
    return force_text(iri_to_uri(resolver._reverse_with_prefix(view, prefix, *args, **kwargs)))
  File "E:\CStone\python\lib\site-packages\django\core\urlresolvers.py", line 496, in _reverse_with_prefix
    (lookup_view_s, args, kwargs, len(patterns), patterns))
NoReverseMatch: Reverse for '/search_results/' with arguments '()' and keyword arguments '{}' not found. 0 pattern(s) tried: []
ERROR 2016-05-10 21:56:52,313 base 6112 2452 Internal Server Error: /genre/1/
Traceback (most recent call last):
  File "E:\CStone\python\lib\site-packages\django\core\handlers\base.py", line 132, in get_response
    response = wrapped_callback(request, *callback_args, **callback_kwargs)
  File "E:\GreedyGames\greedyMusic\views.py", line 35, in viewGenre
    return genereDetailView.as_view()(request, slug=slug)
AttributeError: 'function' object has no attribute 'as_view'
ERROR 2016-05-10 22:10:51,766 base 1824 6724 Internal Server Error: /genre/
Traceback (most recent call last):
  File "E:\CStone\python\lib\site-packages\django\core\handlers\base.py", line 132, in get_response
    response = wrapped_callback(request, *callback_args, **callback_kwargs)
TypeError: viewGenre() takes exactly 2 arguments (1 given)
ERROR 2016-05-11 00:56:10,028 base 1092 6040 Internal Server Error: /genre/1/
Traceback (most recent call last):
  File "E:\CStone\python\lib\site-packages\django\core\handlers\base.py", line 132, in get_response
    response = wrapped_callback(request, *callback_args, **callback_kwargs)
  File "E:\GreedyGames\greedyMusic\views.py", line 37, in viewGenre
    return genereDetailView.as_view()(request, slug=slug)
  File "E:\CStone\python\lib\site-packages\django\views\generic\base.py", line 71, in view
    return self.dispatch(request, *args, **kwargs)
  File "E:\CStone\python\lib\site-packages\django\views\generic\base.py", line 89, in dispatch
    return handler(request, *args, **kwargs)
  File "E:\CStone\python\lib\site-packages\django\views\generic\detail.py", line 115, in get
    self.object = self.get_object()
  File "E:\CStone\python\lib\site-packages\django\views\generic\detail.py", line 32, in get_object
    queryset = self.get_queryset()
  File "E:\CStone\python\lib\site-packages\django\views\generic\detail.py", line 68, in get_queryset
    return self.model._default_manager.all()
AttributeError: type object 'FormForGenre' has no attribute '_default_manager'
ERROR 2016-05-11 01:20:28,924 base 3644 268 Internal Server Error: /genre/1/
Traceback (most recent call last):
  File "E:\CStone\python\lib\site-packages\django\core\handlers\base.py", line 132, in get_response
    response = wrapped_callback(request, *callback_args, **callback_kwargs)
  File "E:\GreedyGames\greedyMusic\views.py", line 37, in viewGenre
    return genereDetailView.as_view()(request, slug=slug)
  File "E:\CStone\python\lib\site-packages\django\views\generic\base.py", line 71, in view
    return self.dispatch(request, *args, **kwargs)
  File "E:\CStone\python\lib\site-packages\django\views\generic\base.py", line 89, in dispatch
    return handler(request, *args, **kwargs)
  File "E:\CStone\python\lib\site-packages\django\views\generic\detail.py", line 115, in get
    self.object = self.get_object()
  File "E:\CStone\python\lib\site-packages\django\views\generic\detail.py", line 32, in get_object
    queryset = self.get_queryset()
  File "E:\CStone\python\lib\site-packages\django\views\generic\detail.py", line 68, in get_queryset
    return self.model._default_manager.all()
AttributeError: type object 'FormForGenre' has no attribute '_default_manager'
ERROR 2016-05-11 11:53:14,585 base 5668 2024 Internal Server Error: /genre/1/
Traceback (most recent call last):
  File "E:\CStone\python\lib\site-packages\django\core\handlers\base.py", line 132, in get_response
    response = wrapped_callback(request, *callback_args, **callback_kwargs)
  File "E:\GreedyGames\greedyMusic\views.py", line 37, in viewGenre
    return genereDetailView.as_view()(request, slug=slug)
  File "E:\CStone\python\lib\site-packages\django\views\generic\base.py", line 71, in view
    return self.dispatch(request, *args, **kwargs)
  File "E:\CStone\python\lib\site-packages\django\views\generic\base.py", line 89, in dispatch
    return handler(request, *args, **kwargs)
  File "E:\CStone\python\lib\site-packages\django\views\generic\detail.py", line 115, in get
    self.object = self.get_object()
  File "E:\CStone\python\lib\site-packages\django\views\generic\detail.py", line 32, in get_object
    queryset = self.get_queryset()
  File "E:\CStone\python\lib\site-packages\django\views\generic\detail.py", line 68, in get_queryset
    return self.model._default_manager.all()
AttributeError: type object 'FormForGenre' has no attribute '_default_manager'
ERROR 2016-05-11 11:57:50,783 base 5668 5564 Internal Server Error: /genre/1/
Traceback (most recent call last):
  File "E:\CStone\python\lib\site-packages\django\core\handlers\base.py", line 132, in get_response
    response = wrapped_callback(request, *callback_args, **callback_kwargs)
  File "E:\GreedyGames\greedyMusic\views.py", line 37, in viewGenre
    return genereDetailView.as_view()(request, slug=slug)
  File "E:\CStone\python\lib\site-packages\django\views\generic\base.py", line 71, in view
    return self.dispatch(request, *args, **kwargs)
  File "E:\CStone\python\lib\site-packages\django\views\generic\base.py", line 89, in dispatch
    return handler(request, *args, **kwargs)
  File "E:\CStone\python\lib\site-packages\django\views\generic\detail.py", line 115, in get
    self.object = self.get_object()
  File "E:\CStone\python\lib\site-packages\django\views\generic\detail.py", line 32, in get_object
    queryset = self.get_queryset()
  File "E:\CStone\python\lib\site-packages\django\views\generic\detail.py", line 68, in get_queryset
    return self.model._default_manager.all()
AttributeError: type object 'FormForGenre' has no attribute '_default_manager'
ERROR 2016-05-11 13:07:05,934 base 4076 5864 Internal Server Error: /tracks/
Traceback (most recent call last):
  File "E:\CStone\python\lib\site-packages\django\core\handlers\base.py", line 119, in get_response
    resolver_match = resolver.resolve(request.path_info)
  File "E:\CStone\python\lib\site-packages\django\core\urlresolvers.py", line 366, in resolve
    for pattern in self.url_patterns:
  File "E:\CStone\python\lib\site-packages\django\core\urlresolvers.py", line 402, in url_patterns
    patterns = getattr(self.urlconf_module, "urlpatterns", self.urlconf_module)
  File "E:\CStone\python\lib\site-packages\django\core\urlresolvers.py", line 396, in urlconf_module
    self._urlconf_module = import_module(self.urlconf_name)
  File "E:\CStone\python\lib\importlib\__init__.py", line 37, in import_module
    __import__(name)
  File "E:\GreedyGames\greedyMusic\urls.py", line 27, in <module>
    url(r'^editTracks/', editTracks, name='editTrack'),
NameError: name 'editTracks' is not defined
ERROR 2016-05-11 13:07:40,773 base 4736 2660 Internal Server Error: /tracks/1/
Traceback (most recent call last):
  File "E:\CStone\python\lib\site-packages\django\core\handlers\base.py", line 164, in get_response
    response = response.render()
  File "E:\CStone\python\lib\site-packages\django\template\response.py", line 158, in render
    self.content = self.rendered_content
  File "E:\CStone\python\lib\site-packages\django\template\response.py", line 135, in rendered_content
    content = template.render(context, self._request)
  File "E:\CStone\python\lib\site-packages\django\template\backends\django.py", line 74, in render
    return self.template.render(context)
  File "E:\CStone\python\lib\site-packages\django\template\base.py", line 209, in render
    return self._render(context)
  File "E:\CStone\python\lib\site-packages\django\template\base.py", line 201, in _render
    return self.nodelist.render(context)
  File "E:\CStone\python\lib\site-packages\django\template\base.py", line 903, in render
    bit = self.render_node(node, context)
  File "E:\CStone\python\lib\site-packages\django\template\debug.py", line 79, in render_node
    return node.render(context)
  File "E:\CStone\python\lib\site-packages\django\template\defaulttags.py", line 507, in render
    six.reraise(*exc_info)
  File "E:\CStone\python\lib\site-packages\django\template\defaulttags.py", line 493, in render
    url = reverse(view_name, args=args, kwargs=kwargs, current_app=current_app)
  File "E:\CStone\python\lib\site-packages\django\core\urlresolvers.py", line 579, in reverse
    return force_text(iri_to_uri(resolver._reverse_with_prefix(view, prefix, *args, **kwargs)))
  File "E:\CStone\python\lib\site-packages\django\core\urlresolvers.py", line 496, in _reverse_with_prefix
    (lookup_view_s, args, kwargs, len(patterns), patterns))
NoReverseMatch: Reverse for 'editTrack' with arguments '(1L,)' and keyword arguments '{}' not found. 1 pattern(s) tried: ['editTracks/']
ERROR 2016-05-11 13:45:50,529 base 2516 5788 Internal Server Error: /tracks/1/
Traceback (most recent call last):
  File "E:\CStone\python\lib\site-packages\django\core\handlers\base.py", line 164, in get_response
    response = response.render()
  File "E:\CStone\python\lib\site-packages\django\template\response.py", line 158, in render
    self.content = self.rendered_content
  File "E:\CStone\python\lib\site-packages\django\template\response.py", line 135, in rendered_content
    content = template.render(context, self._request)
  File "E:\CStone\python\lib\site-packages\django\template\backends\django.py", line 74, in render
    return self.template.render(context)
  File "E:\CStone\python\lib\site-packages\django\template\base.py", line 209, in render
    return self._render(context)
  File "E:\CStone\python\lib\site-packages\django\template\base.py", line 201, in _render
    return self.nodelist.render(context)
  File "E:\CStone\python\lib\site-packages\django\template\base.py", line 903, in render
    bit = self.render_node(node, context)
  File "E:\CStone\python\lib\site-packages\django\template\debug.py", line 79, in render_node
    return node.render(context)
  File "E:\CStone\python\lib\site-packages\django\template\defaulttags.py", line 507, in render
    six.reraise(*exc_info)
  File "E:\CStone\python\lib\site-packages\django\template\defaulttags.py", line 493, in render
    url = reverse(view_name, args=args, kwargs=kwargs, current_app=current_app)
  File "E:\CStone\python\lib\site-packages\django\core\urlresolvers.py", line 579, in reverse
    return force_text(iri_to_uri(resolver._reverse_with_prefix(view, prefix, *args, **kwargs)))
  File "E:\CStone\python\lib\site-packages\django\core\urlresolvers.py", line 496, in _reverse_with_prefix
    (lookup_view_s, args, kwargs, len(patterns), patterns))
NoReverseMatch: Reverse for 'track_list' with arguments '('',)' and keyword arguments '{}' not found. 2 pattern(s) tried: ['tracks/', 'tracks/(?P<slug>[^/]+)/$']
